Base de datos 'proyecto_bd' abierta/creada con Ã©xito
{'Protocol': ['TCP'], 'S_IP': '127.0.0.1', 'Timestamp': ['2015/Jun/18 - 22:10:38'], 'D_MAC': ['00:00:00:00:00:00:00:00:00:00:00:00:08:00'], 'S_MAC': ['00:00:00:00:00:00:00:00:00:00:00:00:08:00'], 'TAG': ['Intento de conexion SSH'], 'S_PORT': ['58801'], 'D_PORT': ['22'], 'D_IP': '192.168.0.1', 'Info_RAW': ['Jun 18 22:10:38 debian kernel 12982.320129 MSG=Intento de conexion SSH IN=lo OUT=0 MAC=00:00:00:00:00:00:00:00:00:00:00:00:08:00 SRC=192.168.1.218 DST=192.168.1.218 LEN=52 TOS=0x00 PREC=0x00 TTL=64 ID=35184 DF PROTO=TCP SPT=58801 DPT=22 WINDOW=256 RES=0x00 ACK URGP=0']}
Traceback (most recent call last):
  File "controller.py", line 14, in <module>
    lista = test.join()
  File "/home/debian-moises/Documentos/securityproject/trunk/version-1-0/source.py", line 173, in join
    self.process()
  File "/home/debian-moises/Documentos/securityproject/trunk/version-1-0/source.py", line 143, in process
    self._db_.insert_row('events',self.dictionary)
  File "/home/debian-moises/Documentos/securityproject/trunk/version-1-0/databasemodel.py", line 157, in insert_row
    self.rows_value = self.check_columns_insert(table_name,values.get_rows())
AttributeError: 'dict' object has no attribute 'get_rows'
